<sdf version='1.6'>
  <world name='default'>
    <physics name='default_physics' default='0' type='ode'>
      <ode>
        <solver>
          <type>quick</type>
          <iters>100</iters>
          <sor>1</sor>
          <use_dynamic_moi_rescaling>0</use_dynamic_moi_rescaling>
        </solver>
        <constraints>
          <cfm>0</cfm>
          <erp>0.9</erp>
          <contact_max_correcting_vel>0.1</contact_max_correcting_vel>
          <contact_surface_layer>0</contact_surface_layer>
        </constraints>
      </ode>
      <real_time_update_rate>1000</real_time_update_rate>
      <max_step_size>0.001</max_step_size>
      <real_time_factor>1</real_time_factor>
    </physics>
    <scene>
      <sky>
        <clouds>
          <speed>12</speed>
        </clouds>
      </sky>
      <ambient>0.4 0.4 0.4 1</ambient>
      <background>0.25 0.25 0.25 1</background>
      <shadows>1</shadows>
    </scene>
    <model name='ground_plane'>
      <static>1</static>
      <link name='link'>
        <collision name='collision'>
          <geometry>
            <plane>
              <normal>0 0 1</normal>
              <size>5000 5000</size>
            </plane>
          </geometry>
          <surface>
            <friction>
              <ode>
                <mu>1</mu>
                <mu2>1</mu2>
              </ode>
              <torsional>
                <ode/>
              </torsional>
            </friction>
            <contact>
              <ode/>
            </contact>
            <bounce/>
          </surface>
          <max_contacts>10</max_contacts>
        </collision>
        <visual name='runway'>
          <pose frame=''>0 0 0.005 0 -0 0</pose>
          <cast_shadows>0</cast_shadows>
          <geometry>
            <plane>
              <normal>0 0 1</normal>
              <size>1829 45</size>
            </plane>
          </geometry>
          <material>
            <script>
              <uri>file://media/materials/scripts/gazebo.material</uri>
              <name>Gazebo/Runway</name>
            </script>
          </material>
        </visual>
        <visual name='grass'>
          <pose frame=''>0 0 -0.1 0 -0 0</pose>
          <cast_shadows>0</cast_shadows>
          <geometry>
            <plane>
              <normal>0 0 1</normal>
              <size>5000 5000</size>
            </plane>
          </geometry>
          <material>
            <script>
              <uri>file://media/materials/scripts/gazebo.material</uri>
              <name>Gazebo/Grass</name>
            </script>
          </material>
        </visual>
        <self_collide>0</self_collide>
        <enable_wind>0</enable_wind>
        <kinematic>0</kinematic>
      </link>
    </model>
    <light name='sun' type='directional'>
      <cast_shadows>1</cast_shadows>
      <pose frame=''>0 0 10 0 -0 0</pose>
      <diffuse>0.8 0.8 0.8 1</diffuse>
      <specular>0.2 0.2 0.2 1</specular>
      <attenuation>
        <range>1000</range>
        <constant>0.9</constant>
        <linear>0.01</linear>
        <quadratic>0.001</quadratic>
      </attenuation>
      <direction>-0.5 0.1 -0.9</direction>
    </light>
    <model name='SkywalkerX8_Red'>
      <link name='skywalker_x8_red::cam_link'>
        <pose frame=''>0 0 0.246 0 -0 0</pose>
        <inertial>
          <mass>0.01</mass>
          <inertia>
            <ixx>0.0001</ixx>
            <iyy>0.0001</iyy>
            <izz>0.0001</izz>
            <ixy>0</ixy>
            <ixz>0</ixz>
            <iyz>0</iyz>
          </inertia>
          <pose frame=''>0 0 0 0 -0 0</pose>
        </inertial>
        <sensor name='chase_cam_wide' type='camera'>
          <pose frame=''>-10 0 12 -1.5708 1 0</pose>
          <camera name='__default__'>
            <horizontal_fov>1.5</horizontal_fov>
            <image>
              <width>1920</width>
              <height>1080</height>
            </image>
            <clip>
              <near>0.1</near>
              <far>1000</far>
            </clip>
          </camera>
          <always_on>1</always_on>
          <update_rate>60</update_rate>
          <visualize>0</visualize>
        </sensor>
        <self_collide>0</self_collide>
        <enable_wind>0</enable_wind>
        <kinematic>0</kinematic>
      </link>
      <joint name='skywalker_x8_red::virtual_camera_mount' type='fixed'>
        <child>skywalker_x8_red::cam_link</child>
        <parent>skywalker_x8_red::base_link</parent>
        <axis>
          <xyz>0 0 1</xyz>
          <limit>
            <upper>0</upper>
            <lower>0</lower>
          </limit>
          <use_parent_model_frame>0</use_parent_model_frame>
        </axis>
      </joint>
      <link name='skywalker_x8_red::base_link'>
        <pose frame=''>0 0 0.246 0 -0 0</pose>
        <inertial>
          <pose frame=''>0 0 0 0 -0 0</pose>
          <mass>4.5</mass>
          <inertia>
            <ixx>0.45</ixx>
            <ixy>0</ixy>
            <ixz>0.06</ixz>
            <iyy>0.325</iyy>
            <iyz>0</iyz>
            <izz>0.75</izz>
          </inertia>
        </inertial>
        <collision name='base_link_collision'>
          <pose frame=''>0 0 -0.07 0 -0 0</pose>
          <geometry>
            <box>
              <size>0.8 2.15 0.2</size>
            </box>
          </geometry>
          <max_contacts>10</max_contacts>
          <surface>
            <contact>
              <ode/>
            </contact>
            <bounce/>
            <friction>
              <torsional>
                <ode/>
              </torsional>
              <ode/>
            </friction>
          </surface>
        </collision>
        <visual name='base_link_visual'>
          <geometry>
            <mesh>
              <uri>model://skywalker_x8/meshes/x8_wing.dae</uri>
            </mesh>
          </geometry>
          <material>
            <diffuse>1 0 0 1</diffuse>
            <specular>1 1 1 1</specular>
            <script>
              <name>Gazebo/Black</name>
              <uri>file://media/materials/scripts/gazebo.material</uri>
            </script>
          </material>
        </visual>
        <visual name='motor'>
          <pose frame=''>-0.361 0 0 0 1.57 0</pose>
          <geometry>
            <cylinder>
              <length>0.035</length>
              <radius>0.02</radius>
            </cylinder>
          </geometry>
          <material>
            <diffuse>1 1 1 1</diffuse>
            <specular>1 1 1 1</specular>
            <script>
              <name>Gazebo/Red</name>
              <uri>file://media/materials/scripts/gazebo.material</uri>
            </script>
          </material>
        </visual>
        <self_collide>0</self_collide>
        <enable_wind>0</enable_wind>
        <kinematic>0</kinematic>
      </link>
      <link name='skywalker_x8_red::rotor_pusher'>
        <pose frame=''>-0.385 0 0.246 0 1.57 0</pose>
        <inertial>
          <mass>0.025</mass>
          <inertia>
            <ixx>9.75e-06</ixx>
            <ixy>0</ixy>
            <ixz>0</ixz>
            <iyy>0.000166704</iyy>
            <iyz>0</iyz>
            <izz>0.000167604</izz>
          </inertia>
          <pose frame=''>0 0 0 0 -0 0</pose>
        </inertial>
        <collision name='collision'>
          <pose frame=''>0 0 0 0 -0 0</pose>
          <geometry>
            <cylinder>
              <length>0.005</length>
              <radius>0.065</radius>
            </cylinder>
          </geometry>
          <max_contacts>10</max_contacts>
          <surface>
            <contact>
              <ode/>
            </contact>
            <bounce/>
            <friction>
              <torsional>
                <ode/>
              </torsional>
              <ode/>
            </friction>
          </surface>
        </collision>
        <visual name='visual'>
          <pose frame=''>0 0 0 0 -0 0</pose>
          <geometry>
            <mesh>
              <scale>0.8 0.8 0.8</scale>
              <uri>model://skywalker_x8/meshes/iris_prop_ccw.dae</uri>
            </mesh>
          </geometry>
          <material>
            <diffuse>1 1 1 1</diffuse>
            <specular>1 1 1 1</specular>
            <script>
              <name>Gazebo/Orange</name>
              <uri>file://media/materials/scripts/gazebo.material</uri>
            </script>
          </material>
        </visual>
        <self_collide>0</self_collide>
        <enable_wind>0</enable_wind>
        <kinematic>0</kinematic>
      </link>
      <joint name='skywalker_x8_red::rotor_pusher_joint' type='revolute'>
        <child>skywalker_x8_red::rotor_pusher</child>
        <parent>skywalker_x8_red::base_link</parent>
        <axis>
          <xyz>1 0 0</xyz>
          <limit>
            <lower>-1e+16</lower>
            <upper>1e+16</upper>
          </limit>
          <dynamics>
            <damping>0.002</damping>
            <spring_reference>0</spring_reference>
            <spring_stiffness>0</spring_stiffness>
          </dynamics>
          <use_parent_model_frame>1</use_parent_model_frame>
        </axis>
      </joint>
      <link name='skywalker_x8_red::left_elevon'>
        <inertial>
          <mass>0.1</mass>
          <inertia>
            <ixx>0.000102319</ixx>
            <ixy>0</ixy>
            <iyy>0.00334417</iyy>
            <ixz>0</ixz>
            <iyz>0</iyz>
            <izz>0.00344607</izz>
          </inertia>
          <pose frame=''>-0.3 0.75 -0.005 0 -0 0</pose>
        </inertial>
        <visual name='left_elevon_visual'>
          <geometry>
            <mesh>
              <uri>model://skywalker_x8/meshes/x8_elevon_left.dae</uri>
            </mesh>
          </geometry>
          <material>
            <diffuse>1 1 1 1</diffuse>
            <specular>1 1 1 1</specular>
            <script>
              <name>Gazebo/Red</name>
              <uri>file://media/materials/scripts/gazebo.material</uri>
            </script>
          </material>
        </visual>
        <pose frame=''>0 0 0.246 0 -0 0</pose>
        <self_collide>0</self_collide>
        <enable_wind>0</enable_wind>
        <kinematic>0</kinematic>
      </link>
      <joint name='skywalker_x8_red::left_elevon_joint' type='revolute'>
        <parent>skywalker_x8_red::base_link</parent>
        <child>skywalker_x8_red::left_elevon</child>
        <pose frame=''>-0.27 0.6 -0.005 0 -0 0.265</pose>
        <axis>
          <xyz>0 1 0</xyz>
          <limit>
            <lower>-0.53</lower>
            <upper>0.53</upper>
          </limit>
          <dynamics>
            <damping>0.1</damping>
            <spring_reference>0</spring_reference>
            <spring_stiffness>0</spring_stiffness>
          </dynamics>
          <use_parent_model_frame>0</use_parent_model_frame>
        </axis>
      </joint>
      <link name='skywalker_x8_red::right_elevon'>
        <inertial>
          <mass>0.1</mass>
          <inertia>
            <ixx>0.000102319</ixx>
            <ixy>0</ixy>
            <iyy>0.00334417</iyy>
            <ixz>0</ixz>
            <iyz>0</iyz>
            <izz>0.00344607</izz>
          </inertia>
          <pose frame=''>-0.3 -0.75 -0.005 0 -0 0</pose>
        </inertial>
        <visual name='right_elevon_visual'>
          <geometry>
            <mesh>
              <uri>model://skywalker_x8/meshes/x8_elevon_right.dae</uri>
            </mesh>
          </geometry>
          <material>
            <diffuse>1 1 1 1</diffuse>
            <specular>1 1 1 1</specular>
            <script>
              <name>Gazebo/Red</name>
              <uri>file://media/materials/scripts/gazebo.material</uri>
            </script>
          </material>
        </visual>
        <pose frame=''>0 0 0.246 0 -0 0</pose>
        <self_collide>0</self_collide>
        <enable_wind>0</enable_wind>
        <kinematic>0</kinematic>
      </link>
      <joint name='skywalker_x8_red::right_elevon_joint' type='revolute'>
        <parent>skywalker_x8_red::base_link</parent>
        <child>skywalker_x8_red::right_elevon</child>
        <pose frame=''>-0.27 -0.6 -0.005 0 0 -0.265</pose>
        <axis>
          <xyz>0 1 0</xyz>
          <limit>
            <lower>-0.53</lower>
            <upper>0.53</upper>
          </limit>
          <dynamics>
            <damping>0.1</damping>
            <spring_reference>0</spring_reference>
            <spring_stiffness>0</spring_stiffness>
          </dynamics>
          <use_parent_model_frame>0</use_parent_model_frame>
        </axis>
      </joint>
      <link name='skywalker_x8_red::imu_link'>
        <inertial>
          <pose frame=''>0 0 0 0 -0 0</pose>
          <mass>0.15</mass>
          <inertia>
            <ixx>1e-05</ixx>
            <ixy>0</ixy>
            <ixz>0</ixz>
            <iyy>2e-05</iyy>
            <iyz>0</iyz>
            <izz>2e-05</izz>
          </inertia>
        </inertial>
        <sensor name='imu_sensor' type='imu'>
          <pose frame=''>0 0 0 -3.14159 -0 0</pose>
          <always_on>1</always_on>
          <update_rate>1000</update_rate>
          <visualize>1</visualize>
          <topic>__default_topic__</topic>
          <plugin name='imu_plugin' filename='libgazebo_ros_imu_sensor.so'>
            <topicName>imu</topicName>
            <bodyName>skywalker_x8_red::imu_link</bodyName>
            <updateRateHZ>10.0</updateRateHZ>
            <gaussianNoise>0.0</gaussianNoise>
            <xyzOffset>0 0 0</xyzOffset>
            <rpyOffset>0 0 0</rpyOffset>
            <frameName>skywalker_x8_red::imu_link</frameName>
            <initialOrientationAsReference>0</initialOrientationAsReference>
          </plugin>
          <imu/>
        </sensor>
        <pose frame=''>0 0 0.246 0 -0 0</pose>
        <self_collide>0</self_collide>
        <enable_wind>0</enable_wind>
        <kinematic>0</kinematic>
      </link>
      <joint name='skywalker_x8_red::skywalker_x8/imu_joint' type='revolute'>
        <child>skywalker_x8_red::imu_link</child>
        <parent>skywalker_x8_red::base_link</parent>
        <axis>
          <xyz>0 0 1</xyz>
          <limit>
            <lower>0</lower>
            <upper>0</upper>
            <effort>0</effort>
            <velocity>0</velocity>
          </limit>
          <dynamics>
            <damping>1</damping>
            <spring_reference>0</spring_reference>
            <spring_stiffness>0</spring_stiffness>
          </dynamics>
          <use_parent_model_frame>1</use_parent_model_frame>
        </axis>
        <physics>
          <ode>
            <implicit_spring_damper>1</implicit_spring_damper>
            <limit>
              <cfm>0</cfm>
              <erp>0.2</erp>
            </limit>
          </ode>
        </physics>
      </joint>
      <plugin name='x8_elevonleftbody_lift' filename='libLiftDragPlugin.so'>
        <a0>0.13</a0>
        <cla>3.7</cla>
        <cda>0.06417112299</cda>
        <cma>-1.8</cma>
        <alpha_stall>0.3391428111</alpha_stall>
        <cla_stall>-3.85</cla_stall>
        <cda_stall>-0.9233984055</cda_stall>
        <cma_stall>0</cma_stall>
        <cp>0.01 0 0</cp>
        <area>0.80</area>
        <air_density>1.2041</air_density>
        <forward>1 0 0</forward>
        <upward>0 0 1</upward>
        <link_name>skywalker_x8_red::base_link</link_name>
      </plugin>
      <plugin name='x8_elevonleft_lift' filename='libLiftDragPlugin.so'>
        <a0>0.15</a0>
        <cla>6.8</cla>
        <cda>0.06417112299</cda>
        <cma>-1.8</cma>
        <alpha_stall>0.6391428111</alpha_stall>
        <cla_stall>-3.85</cla_stall>
        <cda_stall>-0.9233984055</cda_stall>
        <cma_stall>0</cma_stall>
        <cp>-0.30 0.75 -0.005</cp>
        <area>0.10</area>
        <air_density>1.2041</air_density>
        <forward>1 0 0</forward>
        <upward>0 0 1</upward>
        <link_name>skywalker_x8_red::left_elevon</link_name>
      </plugin>
      <plugin name='x8_elevonright_lift' filename='libLiftDragPlugin.so'>
        <a0>0.15</a0>
        <cla>6.8</cla>
        <cda>0.06417112299</cda>
        <cma>-1.8</cma>
        <alpha_stall>0.6391428111</alpha_stall>
        <cla_stall>-3.85</cla_stall>
        <cda_stall>-0.9233984055</cda_stall>
        <cma_stall>0</cma_stall>
        <cp>-0.30 -0.75 -0.005</cp>
        <area>0.10</area>
        <air_density>1.2041</air_density>
        <forward>1 0 0</forward>
        <upward>0 0 1</upward>
        <link_name>skywalker_x8_red::right_elevon</link_name>
      </plugin>
      <plugin name='x8_propeller1_lift' filename='libLiftDragPlugin.so'>
        <a0>0.30</a0>
        <alpha_stall>1.4</alpha_stall>
        <cla>4.2500</cla>
        <cda>0.10</cda>
        <cma>0.00</cma>
        <cla_stall>-0.025</cla_stall>
        <cda_stall>0.0</cda_stall>
        <cma_stall>0.0</cma_stall>
        <area>0.02</area>
        <air_density>1.2041</air_density>
        <cp>0.074205 0 0</cp>
        <forward>0 1 0</forward>
        <upward>0 0 1</upward>
        <link_name>skywalker_x8_red::rotor_pusher</link_name>
      </plugin>
      <plugin name='x8_propeller2_lift' filename='libLiftDragPlugin.so'>
        <a0>0.30</a0>
        <alpha_stall>1.4</alpha_stall>
        <cla>4.2500</cla>
        <cda>0.10</cda>
        <cma>0.00</cma>
        <cla_stall>-0.025</cla_stall>
        <cda_stall>0.0</cda_stall>
        <cma_stall>0.0</cma_stall>
        <area>0.02</area>
        <air_density>1.2041</air_density>
        <cp>-0.074205 0 0</cp>
        <forward>0 -1 0</forward>
        <upward>0 0 1</upward>
        <link_name>skywalker_x8_red::rotor_pusher</link_name>
      </plugin>
      <plugin name='left_winglet_lift' filename='libLiftDragPlugin.so'>
        <a0>0.0</a0>
        <cla>4.752798721</cla>
        <cda>0.6417112299</cda>
        <cma>-1.8</cma>
        <alpha_stall>0.3391428111</alpha_stall>
        <cla_stall>-3.85</cla_stall>
        <cda_stall>-0.9233984055</cda_stall>
        <cma_stall>0</cma_stall>
        <cp>-0.36 1.04 0.08</cp>
        <area>0.12</area>
        <air_density>1.2041</air_density>
        <forward>1 0 0</forward>
        <upward>0 1 0</upward>
        <link_name>skywalker_x8_red::base_link</link_name>
      </plugin>
      <plugin name='right_winglet_lift' filename='libLiftDragPlugin.so'>
        <a0>0.0</a0>
        <cla>4.752798721</cla>
        <cda>0.6417112299</cda>
        <cma>-1.8</cma>
        <alpha_stall>0.3391428111</alpha_stall>
        <cla_stall>-3.85</cla_stall>
        <cda_stall>-0.9233984055</cda_stall>
        <cma_stall>0</cma_stall>
        <cp>-0.36 -1.04 0.08</cp>
        <area>0.12</area>
        <air_density>1.2041</air_density>
        <forward>1 0 0</forward>
        <upward>0 -1 0</upward>
        <link_name>skywalker_x8_red::base_link</link_name>
      </plugin>
      <plugin name='ArduPilotPlugin' filename='libArduPilotPlugin.so'>
        <fdm_addr>127.0.0.1</fdm_addr>
        <fdm_port_in>9002</fdm_port_in>
        <fdm_port_out>9003</fdm_port_out>
        <connectionTimeoutMaxCount>5</connectionTimeoutMaxCount>
        <lock_step>1</lock_step>
        <modelXYZToAirplaneXForwardZDown>0 0 0 3.141593 0 0</modelXYZToAirplaneXForwardZDown>
        <gazeboXYZToNED>0 0 0 3.141593 0 0</gazeboXYZToNED>
        <imuName>imu_sensor</imuName>
        <control channel='0'>
          <jointName>skywalker_x8_red::left_elevon_joint</jointName>
          <multiplier>1.048</multiplier>
          <offset>-0.5</offset>
          <servo_min>1100</servo_min>
          <servo_max>1900</servo_max>
          <type>POSITION</type>
          <p_gain>10.0</p_gain>
          <i_gain>0</i_gain>
          <d_gain>0</d_gain>
          <i_max>0</i_max>
          <i_min>0</i_min>
          <cmd_max>2.5</cmd_max>
          <cmd_min>-2.5</cmd_min>
        </control>
        <control channel='1'>
          <jointName>skywalker_x8_red::right_elevon_joint</jointName>
          <multiplier>1.048</multiplier>
          <offset>-0.5</offset>
          <servo_min>1100</servo_min>
          <servo_max>1900</servo_max>
          <type>POSITION</type>
          <p_gain>10.0</p_gain>
          <i_gain>0</i_gain>
          <d_gain>0</d_gain>
          <i_max>0</i_max>
          <i_min>0</i_min>
          <cmd_max>2.5</cmd_max>
          <cmd_min>-2.5</cmd_min>
        </control>
        <control channel='2'>
          <jointName>skywalker_x8_red::rotor_pusher_joint</jointName>
          <multiplier>838</multiplier>
          <offset>0</offset>
          <servo_min>1200</servo_min>
          <servo_max>2000</servo_max>
          <type>VELOCITY</type>
          <p_gain>0.20</p_gain>
          <i_gain>0</i_gain>
          <d_gain>0</d_gain>
          <i_max>0</i_max>
          <i_min>0</i_min>
          <cmd_max>2.5</cmd_max>
          <cmd_min>-2.5</cmd_min>
        </control>
      </plugin>
      <pose frame=''>0 0 0 0 -0 0</pose>
    </model>
    <model name='SkywalkerX8_Green'>
      <link name='skywalker_x8_green::cam_link'>
        <pose frame=''>0 0 0.246 0 -0 0</pose>
        <inertial>
          <mass>0.01</mass>
          <inertia>
            <ixx>0.0001</ixx>
            <iyy>0.0001</iyy>
            <izz>0.0001</izz>
            <ixy>0</ixy>
            <ixz>0</ixz>
            <iyz>0</iyz>
          </inertia>
          <pose frame=''>0 0 0 0 -0 0</pose>
        </inertial>
        <sensor name='chase_cam_wide' type='camera'>
          <pose frame=''>0 -4 4 0 0.6 1.4</pose>
          <camera name='__default__'>
            <horizontal_fov>1.5</horizontal_fov>
            <image>
              <width>1920</width>
              <height>1080</height>
            </image>
            <clip>
              <near>0.1</near>
              <far>1000</far>
            </clip>
          </camera>
          <always_on>1</always_on>
          <update_rate>60</update_rate>
          <visualize>0</visualize>
        </sensor>
        <self_collide>0</self_collide>
        <enable_wind>0</enable_wind>
        <kinematic>0</kinematic>
      </link>
      <joint name='skywalker_x8_green::virtual_camera_mount' type='fixed'>
        <child>skywalker_x8_green::cam_link</child>
        <parent>skywalker_x8_green::base_link</parent>
        <axis>
          <xyz>0 0 1</xyz>
          <limit>
            <upper>0</upper>
            <lower>0</lower>
          </limit>
          <use_parent_model_frame>0</use_parent_model_frame>
        </axis>
      </joint>
      <link name='skywalker_x8_green::base_link'>
        <pose frame=''>0 0 0.246 0 -0 0</pose>
        <inertial>
          <pose frame=''>0 0 0 0 -0 0</pose>
          <mass>4.5</mass>
          <inertia>
            <ixx>0.45</ixx>
            <ixy>0</ixy>
            <ixz>0.06</ixz>
            <iyy>0.325</iyy>
            <iyz>0</iyz>
            <izz>0.75</izz>
          </inertia>
        </inertial>
        <collision name='base_link_collision'>
          <pose frame=''>0 0 -0.07 0 -0 0</pose>
          <geometry>
            <box>
              <size>0.8 2.15 0.2</size>
            </box>
          </geometry>
          <max_contacts>10</max_contacts>
          <surface>
            <contact>
              <ode/>
            </contact>
            <bounce/>
            <friction>
              <torsional>
                <ode/>
              </torsional>
              <ode/>
            </friction>
          </surface>
        </collision>
        <visual name='base_link_visual'>
          <geometry>
            <mesh>
              <uri>model://skywalker_x8/meshes/x8_wing.dae</uri>
            </mesh>
          </geometry>
          <material>
            <diffuse>0 1 1 1</diffuse>
            <specular>1 1 1 1</specular>
            <script>
              <name>Gazebo/Black</name>
              <uri>file://media/materials/scripts/gazebo.material</uri>
            </script>
          </material>
        </visual>
        <visual name='motor'>
          <pose frame=''>-0.361 0 0 0 1.57 0</pose>
          <geometry>
            <cylinder>
              <length>0.035</length>
              <radius>0.02</radius>
            </cylinder>
          </geometry>
          <material>
            <diffuse>1 1 1 1</diffuse>
            <specular>1 1 1 1</specular>
            <script>
              <name>Gazebo/Green</name>
              <uri>file://media/materials/scripts/gazebo.material</uri>
            </script>
          </material>
        </visual>
        <self_collide>0</self_collide>
        <enable_wind>0</enable_wind>
        <kinematic>0</kinematic>
      </link>
      <link name='skywalker_x8_green::rotor_pusher'>
        <pose frame=''>-0.385 0 0.246 0 1.57 0</pose>
        <inertial>
          <mass>0.025</mass>
          <inertia>
            <ixx>9.75e-06</ixx>
            <ixy>0</ixy>
            <ixz>0</ixz>
            <iyy>0.000166704</iyy>
            <iyz>0</iyz>
            <izz>0.000167604</izz>
          </inertia>
          <pose frame=''>0 0 0 0 -0 0</pose>
        </inertial>
        <collision name='collision'>
          <pose frame=''>0 0 0 0 -0 0</pose>
          <geometry>
            <cylinder>
              <length>0.005</length>
              <radius>0.065</radius>
            </cylinder>
          </geometry>
          <max_contacts>10</max_contacts>
          <surface>
            <contact>
              <ode/>
            </contact>
            <bounce/>
            <friction>
              <torsional>
                <ode/>
              </torsional>
              <ode/>
            </friction>
          </surface>
        </collision>
        <visual name='visual'>
          <pose frame=''>0 0 0 0 -0 0</pose>
          <geometry>
            <mesh>
              <scale>0.8 0.8 0.8</scale>
              <uri>model://skywalker_x8/meshes/iris_prop_ccw.dae</uri>
            </mesh>
          </geometry>
          <material>
            <diffuse>1 1 1 1</diffuse>
            <specular>1 1 1 1</specular>
            <script>
              <name>Gazebo/Orange</name>
              <uri>file://media/materials/scripts/gazebo.material</uri>
            </script>
          </material>
        </visual>
        <self_collide>0</self_collide>
        <enable_wind>0</enable_wind>
        <kinematic>0</kinematic>
      </link>
      <joint name='skywalker_x8_green::rotor_pusher_joint' type='revolute'>
        <child>skywalker_x8_green::rotor_pusher</child>
        <parent>skywalker_x8_green::base_link</parent>
        <axis>
          <xyz>1 0 0</xyz>
          <limit>
            <lower>-1e+16</lower>
            <upper>1e+16</upper>
          </limit>
          <dynamics>
            <damping>0.002</damping>
            <spring_reference>0</spring_reference>
            <spring_stiffness>0</spring_stiffness>
          </dynamics>
          <use_parent_model_frame>1</use_parent_model_frame>
        </axis>
      </joint>
      <link name='skywalker_x8_green::left_elevon'>
        <inertial>
          <mass>0.1</mass>
          <inertia>
            <ixx>0.000102319</ixx>
            <ixy>0</ixy>
            <iyy>0.00334417</iyy>
            <ixz>0</ixz>
            <iyz>0</iyz>
            <izz>0.00344607</izz>
          </inertia>
          <pose frame=''>-0.3 0.75 -0.005 0 -0 0</pose>
        </inertial>
        <visual name='left_elevon_visual'>
          <geometry>
            <mesh>
              <uri>model://skywalker_x8/meshes/x8_elevon_left.dae</uri>
            </mesh>
          </geometry>
          <material>
            <diffuse>1 1 1 1</diffuse>
            <specular>1 1 1 1</specular>
            <script>
              <name>Gazebo/Red</name>
              <uri>file://media/materials/scripts/gazebo.material</uri>
            </script>
          </material>
        </visual>
        <pose frame=''>0 0 0.246 0 -0 0</pose>
        <self_collide>0</self_collide>
        <enable_wind>0</enable_wind>
        <kinematic>0</kinematic>
      </link>
      <joint name='skywalker_x8_green::left_elevon_joint' type='revolute'>
        <parent>skywalker_x8_green::base_link</parent>
        <child>skywalker_x8_green::left_elevon</child>
        <pose frame=''>-0.27 0.6 -0.005 0 -0 0.265</pose>
        <axis>
          <xyz>0 1 0</xyz>
          <limit>
            <lower>-0.53</lower>
            <upper>0.53</upper>
          </limit>
          <dynamics>
            <damping>0.1</damping>
            <spring_reference>0</spring_reference>
            <spring_stiffness>0</spring_stiffness>
          </dynamics>
          <use_parent_model_frame>0</use_parent_model_frame>
        </axis>
      </joint>
      <link name='skywalker_x8_green::right_elevon'>
        <inertial>
          <mass>0.1</mass>
          <inertia>
            <ixx>0.000102319</ixx>
            <ixy>0</ixy>
            <iyy>0.00334417</iyy>
            <ixz>0</ixz>
            <iyz>0</iyz>
            <izz>0.00344607</izz>
          </inertia>
          <pose frame=''>-0.3 -0.75 -0.005 0 -0 0</pose>
        </inertial>
        <visual name='right_elevon_visual'>
          <geometry>
            <mesh>
              <uri>model://skywalker_x8/meshes/x8_elevon_right.dae</uri>
            </mesh>
          </geometry>
          <material>
            <diffuse>1 1 1 1</diffuse>
            <specular>1 1 1 1</specular>
            <script>
              <name>Gazebo/Red</name>
              <uri>file://media/materials/scripts/gazebo.material</uri>
            </script>
          </material>
        </visual>
        <pose frame=''>0 0 0.246 0 -0 0</pose>
        <self_collide>0</self_collide>
        <enable_wind>0</enable_wind>
        <kinematic>0</kinematic>
      </link>
      <joint name='skywalker_x8_green::right_elevon_joint' type='revolute'>
        <parent>skywalker_x8_green::base_link</parent>
        <child>skywalker_x8_green::right_elevon</child>
        <pose frame=''>-0.27 -0.6 -0.005 0 0 -0.265</pose>
        <axis>
          <xyz>0 1 0</xyz>
          <limit>
            <lower>-0.53</lower>
            <upper>0.53</upper>
          </limit>
          <dynamics>
            <damping>0.1</damping>
            <spring_reference>0</spring_reference>
            <spring_stiffness>0</spring_stiffness>
          </dynamics>
          <use_parent_model_frame>0</use_parent_model_frame>
        </axis>
      </joint>
      <link name='skywalker_x8_green::imu_link'>
        <inertial>
          <pose frame=''>0 0 0 0 -0 0</pose>
          <mass>0.15</mass>
          <inertia>
            <ixx>1e-05</ixx>
            <ixy>0</ixy>
            <ixz>0</ixz>
            <iyy>2e-05</iyy>
            <iyz>0</iyz>
            <izz>2e-05</izz>
          </inertia>
        </inertial>
        <sensor name='imu_sensor' type='imu'>
          <pose frame=''>0 0 0 -3.14159 -0 0</pose>
          <always_on>1</always_on>
          <update_rate>1000</update_rate>
          <visualize>1</visualize>
          <topic>__default_topic__</topic>
          <plugin name='imu_plugin' filename='libgazebo_ros_imu_sensor.so'>
            <topicName>imu</topicName>
            <bodyName>skywalker_x8_green::imu_link</bodyName>
            <updateRateHZ>10.0</updateRateHZ>
            <gaussianNoise>0.0</gaussianNoise>
            <xyzOffset>0 0 0</xyzOffset>
            <rpyOffset>0 0 0</rpyOffset>
            <frameName>skywalker_x8_green::imu_link</frameName>
            <initialOrientationAsReference>0</initialOrientationAsReference>
          </plugin>
          <imu/>
        </sensor>
        <pose frame=''>0 0 0.246 0 -0 0</pose>
        <self_collide>0</self_collide>
        <enable_wind>0</enable_wind>
        <kinematic>0</kinematic>
      </link>
      <joint name='skywalker_x8_green::skywalker_x8/imu_joint' type='revolute'>
        <child>skywalker_x8_green::imu_link</child>
        <parent>skywalker_x8_green::base_link</parent>
        <axis>
          <xyz>0 0 1</xyz>
          <limit>
            <lower>0</lower>
            <upper>0</upper>
            <effort>0</effort>
            <velocity>0</velocity>
          </limit>
          <dynamics>
            <damping>1</damping>
            <spring_reference>0</spring_reference>
            <spring_stiffness>0</spring_stiffness>
          </dynamics>
          <use_parent_model_frame>1</use_parent_model_frame>
        </axis>
        <physics>
          <ode>
            <implicit_spring_damper>1</implicit_spring_damper>
            <limit>
              <cfm>0</cfm>
              <erp>0.2</erp>
            </limit>
          </ode>
        </physics>
      </joint>
      <plugin name='x8_elevonleftbody_lift' filename='libLiftDragPlugin.so'>
        <a0>0.13</a0>
        <cla>3.7</cla>
        <cda>0.06417112299</cda>
        <cma>-1.8</cma>
        <alpha_stall>0.3391428111</alpha_stall>
        <cla_stall>-3.85</cla_stall>
        <cda_stall>-0.9233984055</cda_stall>
        <cma_stall>0</cma_stall>
        <cp>0.01 0 0</cp>
        <area>0.80</area>
        <air_density>1.2041</air_density>
        <forward>1 0 0</forward>
        <upward>0 0 1</upward>
        <link_name>skywalker_x8_green::base_link</link_name>
      </plugin>
      <plugin name='x8_elevonleft_lift' filename='libLiftDragPlugin.so'>
        <a0>0.15</a0>
        <cla>6.8</cla>
        <cda>0.06417112299</cda>
        <cma>-1.8</cma>
        <alpha_stall>0.6391428111</alpha_stall>
        <cla_stall>-3.85</cla_stall>
        <cda_stall>-0.9233984055</cda_stall>
        <cma_stall>0</cma_stall>
        <cp>-0.30 0.75 -0.005</cp>
        <area>0.10</area>
        <air_density>1.2041</air_density>
        <forward>1 0 0</forward>
        <upward>0 0 1</upward>
        <link_name>skywalker_x8_green::left_elevon</link_name>
      </plugin>
      <plugin name='x8_elevonright_lift' filename='libLiftDragPlugin.so'>
        <a0>0.15</a0>
        <cla>6.8</cla>
        <cda>0.06417112299</cda>
        <cma>-1.8</cma>
        <alpha_stall>0.6391428111</alpha_stall>
        <cla_stall>-3.85</cla_stall>
        <cda_stall>-0.9233984055</cda_stall>
        <cma_stall>0</cma_stall>
        <cp>-0.30 -0.75 -0.005</cp>
        <area>0.10</area>
        <air_density>1.2041</air_density>
        <forward>1 0 0</forward>
        <upward>0 0 1</upward>
        <link_name>skywalker_x8_green::right_elevon</link_name>
      </plugin>
      <plugin name='x8_propeller1_lift' filename='libLiftDragPlugin.so'>
        <a0>0.30</a0>
        <alpha_stall>1.4</alpha_stall>
        <cla>4.2500</cla>
        <cda>0.10</cda>
        <cma>0.00</cma>
        <cla_stall>-0.025</cla_stall>
        <cda_stall>0.0</cda_stall>
        <cma_stall>0.0</cma_stall>
        <area>0.02</area>
        <air_density>1.2041</air_density>
        <cp>0.074205 0 0</cp>
        <forward>0 1 0</forward>
        <upward>0 0 1</upward>
        <link_name>skywalker_x8_green::rotor_pusher</link_name>
      </plugin>
      <plugin name='x8_propeller2_lift' filename='libLiftDragPlugin.so'>
        <a0>0.30</a0>
        <alpha_stall>1.4</alpha_stall>
        <cla>4.2500</cla>
        <cda>0.10</cda>
        <cma>0.00</cma>
        <cla_stall>-0.025</cla_stall>
        <cda_stall>0.0</cda_stall>
        <cma_stall>0.0</cma_stall>
        <area>0.02</area>
        <air_density>1.2041</air_density>
        <cp>-0.074205 0 0</cp>
        <forward>0 -1 0</forward>
        <upward>0 0 1</upward>
        <link_name>skywalker_x8_green::rotor_pusher</link_name>
      </plugin>
      <plugin name='left_winglet_lift' filename='libLiftDragPlugin.so'>
        <a0>0.0</a0>
        <cla>4.752798721</cla>
        <cda>0.6417112299</cda>
        <cma>-1.8</cma>
        <alpha_stall>0.3391428111</alpha_stall>
        <cla_stall>-3.85</cla_stall>
        <cda_stall>-0.9233984055</cda_stall>
        <cma_stall>0</cma_stall>
        <cp>-0.36 1.04 0.08</cp>
        <area>0.12</area>
        <air_density>1.2041</air_density>
        <forward>1 0 0</forward>
        <upward>0 1 0</upward>
        <link_name>skywalker_x8_green::base_link</link_name>
      </plugin>
      <plugin name='right_winglet_lift' filename='libLiftDragPlugin.so'>
        <a0>0.0</a0>
        <cla>4.752798721</cla>
        <cda>0.6417112299</cda>
        <cma>-1.8</cma>
        <alpha_stall>0.3391428111</alpha_stall>
        <cla_stall>-3.85</cla_stall>
        <cda_stall>-0.9233984055</cda_stall>
        <cma_stall>0</cma_stall>
        <cp>-0.36 -1.04 0.08</cp>
        <area>0.12</area>
        <air_density>1.2041</air_density>
        <forward>1 0 0</forward>
        <upward>0 -1 0</upward>
        <link_name>skywalker_x8_green::base_link</link_name>
      </plugin>
      <plugin name='ArduPilotPlugin' filename='libArduPilotPlugin.so'>
        <fdm_addr>127.0.0.1</fdm_addr>
        <fdm_port_in>9012</fdm_port_in>
        <fdm_port_out>9013</fdm_port_out>
        <connectionTimeoutMaxCount>5</connectionTimeoutMaxCount>
        <lock_step>1</lock_step>
        <modelXYZToAirplaneXForwardZDown>0 0 0 3.141593 0 0</modelXYZToAirplaneXForwardZDown>
        <gazeboXYZToNED>0 0 0 3.141593 0 0</gazeboXYZToNED>
        <imuName>imu_sensor</imuName>
        <control channel='0'>
          <jointName>skywalker_x8_green::left_elevon_joint</jointName>
          <multiplier>1.048</multiplier>
          <offset>-0.5</offset>
          <servo_min>1100</servo_min>
          <servo_max>1900</servo_max>
          <type>POSITION</type>
          <p_gain>10.0</p_gain>
          <i_gain>0</i_gain>
          <d_gain>0</d_gain>
          <i_max>0</i_max>
          <i_min>0</i_min>
          <cmd_max>2.5</cmd_max>
          <cmd_min>-2.5</cmd_min>
        </control>
        <control channel='1'>
          <jointName>skywalker_x8_green::right_elevon_joint</jointName>
          <multiplier>1.048</multiplier>
          <offset>-0.5</offset>
          <servo_min>1100</servo_min>
          <servo_max>1900</servo_max>
          <type>POSITION</type>
          <p_gain>10.0</p_gain>
          <i_gain>0</i_gain>
          <d_gain>0</d_gain>
          <i_max>0</i_max>
          <i_min>0</i_min>
          <cmd_max>2.5</cmd_max>
          <cmd_min>-2.5</cmd_min>
        </control>
        <control channel='2'>
          <jointName>skywalker_x8_green::rotor_pusher_joint</jointName>
          <multiplier>838</multiplier>
          <offset>0</offset>
          <servo_min>1200</servo_min>
          <servo_max>2000</servo_max>
          <type>VELOCITY</type>
          <p_gain>0.20</p_gain>
          <i_gain>0</i_gain>
          <d_gain>0</d_gain>
          <i_max>0</i_max>
          <i_min>0</i_min>
          <cmd_max>2.5</cmd_max>
          <cmd_min>-2.5</cmd_min>
        </control>
      </plugin>
      <pose frame=''>-3 -1.732 0 0 -0 0</pose>
    </model>
    <model name='SkywalkerX8_Blue'>
      <link name='skywalker_x8_blue::cam_link'>
        <pose frame=''>0 0 0.246 0 -0 0</pose>
        <inertial>
          <mass>0.01</mass>
          <inertia>
            <ixx>0.0001</ixx>
            <iyy>0.0001</iyy>
            <izz>0.0001</izz>
            <ixy>0</ixy>
            <ixz>0</ixz>
            <iyz>0</iyz>
          </inertia>
          <pose frame=''>0 0 0 0 -0 0</pose>
        </inertial>
        <sensor name='chase_cam_wide' type='camera'>
          <pose frame=''>0 4 4 -0 0.6 -1.4</pose>
          <camera name='__default__'>
            <horizontal_fov>1.5</horizontal_fov>
            <image>
              <width>1920</width>
              <height>1080</height>
            </image>
            <clip>
              <near>0.1</near>
              <far>1000</far>
            </clip>
          </camera>
          <always_on>1</always_on>
          <update_rate>60</update_rate>
          <visualize>0</visualize>
        </sensor>
        <self_collide>0</self_collide>
        <enable_wind>0</enable_wind>
        <kinematic>0</kinematic>
      </link>
      <joint name='skywalker_x8_blue::virtual_camera_mount' type='fixed'>
        <child>skywalker_x8_blue::cam_link</child>
        <parent>skywalker_x8_blue::base_link</parent>
        <axis>
          <xyz>0 0 1</xyz>
          <limit>
            <upper>0</upper>
            <lower>0</lower>
          </limit>
          <use_parent_model_frame>0</use_parent_model_frame>
        </axis>
      </joint>
      <link name='skywalker_x8_blue::base_link'>
        <pose frame=''>0 0 0.246 0 -0 0</pose>
        <inertial>
          <pose frame=''>0 0 0 0 -0 0</pose>
          <mass>4.5</mass>
          <inertia>
            <ixx>0.45</ixx>
            <ixy>0</ixy>
            <ixz>0.06</ixz>
            <iyy>0.325</iyy>
            <iyz>0</iyz>
            <izz>0.75</izz>
          </inertia>
        </inertial>
        <collision name='base_link_collision'>
          <pose frame=''>0 0 -0.07 0 -0 0</pose>
          <geometry>
            <box>
              <size>0.8 2.15 0.2</size>
            </box>
          </geometry>
          <max_contacts>10</max_contacts>
          <surface>
            <contact>
              <ode/>
            </contact>
            <bounce/>
            <friction>
              <torsional>
                <ode/>
              </torsional>
              <ode/>
            </friction>
          </surface>
        </collision>
        <visual name='base_link_visual'>
          <geometry>
            <mesh>
              <uri>model://skywalker_x8/meshes/x8_wing.dae</uri>
            </mesh>
          </geometry>
          <material>
            <diffuse>0 0 1 1</diffuse>
            <specular>1 1 1 1</specular>
            <script>
              <name>Gazebo/Black</name>
              <uri>file://media/materials/scripts/gazebo.material</uri>
            </script>
          </material>
        </visual>
        <visual name='motor'>
          <pose frame=''>-0.361 0 0 0 1.57 0</pose>
          <geometry>
            <cylinder>
              <length>0.035</length>
              <radius>0.02</radius>
            </cylinder>
          </geometry>
          <material>
            <diffuse>1 1 1 1</diffuse>
            <specular>1 1 1 1</specular>
            <script>
              <name>Gazebo/Blue</name>
              <uri>file://media/materials/scripts/gazebo.material</uri>
            </script>
          </material>
        </visual>
        <self_collide>0</self_collide>
        <enable_wind>0</enable_wind>
        <kinematic>0</kinematic>
      </link>
      <link name='skywalker_x8_blue::rotor_pusher'>
        <pose frame=''>-0.385 0 0.246 0 1.57 0</pose>
        <inertial>
          <mass>0.025</mass>
          <inertia>
            <ixx>9.75e-06</ixx>
            <ixy>0</ixy>
            <ixz>0</ixz>
            <iyy>0.000166704</iyy>
            <iyz>0</iyz>
            <izz>0.000167604</izz>
          </inertia>
          <pose frame=''>0 0 0 0 -0 0</pose>
        </inertial>
        <collision name='collision'>
          <pose frame=''>0 0 0 0 -0 0</pose>
          <geometry>
            <cylinder>
              <length>0.005</length>
              <radius>0.065</radius>
            </cylinder>
          </geometry>
          <max_contacts>10</max_contacts>
          <surface>
            <contact>
              <ode/>
            </contact>
            <bounce/>
            <friction>
              <torsional>
                <ode/>
              </torsional>
              <ode/>
            </friction>
          </surface>
        </collision>
        <visual name='visual'>
          <pose frame=''>0 0 0 0 -0 0</pose>
          <geometry>
            <mesh>
              <scale>0.8 0.8 0.8</scale>
              <uri>model://skywalker_x8/meshes/iris_prop_ccw.dae</uri>
            </mesh>
          </geometry>
          <material>
            <diffuse>1 1 1 1</diffuse>
            <specular>1 1 1 1</specular>
            <script>
              <name>Gazebo/Orange</name>
              <uri>file://media/materials/scripts/gazebo.material</uri>
            </script>
          </material>
        </visual>
        <self_collide>0</self_collide>
        <enable_wind>0</enable_wind>
        <kinematic>0</kinematic>
      </link>
      <joint name='skywalker_x8_blue::rotor_pusher_joint' type='revolute'>
        <child>skywalker_x8_blue::rotor_pusher</child>
        <parent>skywalker_x8_blue::base_link</parent>
        <axis>
          <xyz>1 0 0</xyz>
          <limit>
            <lower>-1e+16</lower>
            <upper>1e+16</upper>
          </limit>
          <dynamics>
            <damping>0.002</damping>
            <spring_reference>0</spring_reference>
            <spring_stiffness>0</spring_stiffness>
          </dynamics>
          <use_parent_model_frame>1</use_parent_model_frame>
        </axis>
      </joint>
      <link name='skywalker_x8_blue::left_elevon'>
        <inertial>
          <mass>0.1</mass>
          <inertia>
            <ixx>0.000102319</ixx>
            <ixy>0</ixy>
            <iyy>0.00334417</iyy>
            <ixz>0</ixz>
            <iyz>0</iyz>
            <izz>0.00344607</izz>
          </inertia>
          <pose frame=''>-0.3 0.75 -0.005 0 -0 0</pose>
        </inertial>
        <visual name='left_elevon_visual'>
          <geometry>
            <mesh>
              <uri>model://skywalker_x8/meshes/x8_elevon_left.dae</uri>
            </mesh>
          </geometry>
          <material>
            <diffuse>1 1 1 1</diffuse>
            <specular>1 1 1 1</specular>
            <script>
              <name>Gazebo/Red</name>
              <uri>file://media/materials/scripts/gazebo.material</uri>
            </script>
          </material>
        </visual>
        <pose frame=''>0 0 0.246 0 -0 0</pose>
        <self_collide>0</self_collide>
        <enable_wind>0</enable_wind>
        <kinematic>0</kinematic>
      </link>
      <joint name='skywalker_x8_blue::left_elevon_joint' type='revolute'>
        <parent>skywalker_x8_blue::base_link</parent>
        <child>skywalker_x8_blue::left_elevon</child>
        <pose frame=''>-0.27 0.6 -0.005 0 -0 0.265</pose>
        <axis>
          <xyz>0 1 0</xyz>
          <limit>
            <lower>-0.53</lower>
            <upper>0.53</upper>
          </limit>
          <dynamics>
            <damping>0.1</damping>
            <spring_reference>0</spring_reference>
            <spring_stiffness>0</spring_stiffness>
          </dynamics>
          <use_parent_model_frame>0</use_parent_model_frame>
        </axis>
      </joint>
      <link name='skywalker_x8_blue::right_elevon'>
        <inertial>
          <mass>0.1</mass>
          <inertia>
            <ixx>0.000102319</ixx>
            <ixy>0</ixy>
            <iyy>0.00334417</iyy>
            <ixz>0</ixz>
            <iyz>0</iyz>
            <izz>0.00344607</izz>
          </inertia>
          <pose frame=''>-0.3 -0.75 -0.005 0 -0 0</pose>
        </inertial>
        <visual name='right_elevon_visual'>
          <geometry>
            <mesh>
              <uri>model://skywalker_x8/meshes/x8_elevon_right.dae</uri>
            </mesh>
          </geometry>
          <material>
            <diffuse>1 1 1 1</diffuse>
            <specular>1 1 1 1</specular>
            <script>
              <name>Gazebo/Red</name>
              <uri>file://media/materials/scripts/gazebo.material</uri>
            </script>
          </material>
        </visual>
        <pose frame=''>0 0 0.246 0 -0 0</pose>
        <self_collide>0</self_collide>
        <enable_wind>0</enable_wind>
        <kinematic>0</kinematic>
      </link>
      <joint name='skywalker_x8_blue::right_elevon_joint' type='revolute'>
        <parent>skywalker_x8_blue::base_link</parent>
        <child>skywalker_x8_blue::right_elevon</child>
        <pose frame=''>-0.27 -0.6 -0.005 0 0 -0.265</pose>
        <axis>
          <xyz>0 1 0</xyz>
          <limit>
            <lower>-0.53</lower>
            <upper>0.53</upper>
          </limit>
          <dynamics>
            <damping>0.1</damping>
            <spring_reference>0</spring_reference>
            <spring_stiffness>0</spring_stiffness>
          </dynamics>
          <use_parent_model_frame>0</use_parent_model_frame>
        </axis>
      </joint>
      <link name='skywalker_x8_blue::imu_link'>
        <inertial>
          <pose frame=''>0 0 0 0 -0 0</pose>
          <mass>0.15</mass>
          <inertia>
            <ixx>1e-05</ixx>
            <ixy>0</ixy>
            <ixz>0</ixz>
            <iyy>2e-05</iyy>
            <iyz>0</iyz>
            <izz>2e-05</izz>
          </inertia>
        </inertial>
        <sensor name='imu_sensor' type='imu'>
          <pose frame=''>0 0 0 -3.14159 -0 0</pose>
          <always_on>1</always_on>
          <update_rate>1000</update_rate>
          <visualize>1</visualize>
          <topic>__default_topic__</topic>
          <plugin name='imu_plugin' filename='libgazebo_ros_imu_sensor.so'>
            <topicName>imu</topicName>
            <bodyName>skywalker_x8_blue::imu_link</bodyName>
            <updateRateHZ>10.0</updateRateHZ>
            <gaussianNoise>0.0</gaussianNoise>
            <xyzOffset>0 0 0</xyzOffset>
            <rpyOffset>0 0 0</rpyOffset>
            <frameName>skywalker_x8_blue::imu_link</frameName>
            <initialOrientationAsReference>0</initialOrientationAsReference>
          </plugin>
          <imu/>
        </sensor>
        <pose frame=''>0 0 0.246 0 -0 0</pose>
        <self_collide>0</self_collide>
        <enable_wind>0</enable_wind>
        <kinematic>0</kinematic>
      </link>
      <joint name='skywalker_x8_blue::skywalker_x8/imu_joint' type='revolute'>
        <child>skywalker_x8_blue::imu_link</child>
        <parent>skywalker_x8_blue::base_link</parent>
        <axis>
          <xyz>0 0 1</xyz>
          <limit>
            <lower>0</lower>
            <upper>0</upper>
            <effort>0</effort>
            <velocity>0</velocity>
          </limit>
          <dynamics>
            <damping>1</damping>
            <spring_reference>0</spring_reference>
            <spring_stiffness>0</spring_stiffness>
          </dynamics>
          <use_parent_model_frame>1</use_parent_model_frame>
        </axis>
        <physics>
          <ode>
            <implicit_spring_damper>1</implicit_spring_damper>
            <limit>
              <cfm>0</cfm>
              <erp>0.2</erp>
            </limit>
          </ode>
        </physics>
      </joint>
      <plugin name='x8_elevonleftbody_lift' filename='libLiftDragPlugin.so'>
        <a0>0.13</a0>
        <cla>3.7</cla>
        <cda>0.06417112299</cda>
        <cma>-1.8</cma>
        <alpha_stall>0.3391428111</alpha_stall>
        <cla_stall>-3.85</cla_stall>
        <cda_stall>-0.9233984055</cda_stall>
        <cma_stall>0</cma_stall>
        <cp>0.01 0 0</cp>
        <area>0.80</area>
        <air_density>1.2041</air_density>
        <forward>1 0 0</forward>
        <upward>0 0 1</upward>
        <link_name>skywalker_x8_blue::base_link</link_name>
      </plugin>
      <plugin name='x8_elevonleft_lift' filename='libLiftDragPlugin.so'>
        <a0>0.15</a0>
        <cla>6.8</cla>
        <cda>0.06417112299</cda>
        <cma>-1.8</cma>
        <alpha_stall>0.6391428111</alpha_stall>
        <cla_stall>-3.85</cla_stall>
        <cda_stall>-0.9233984055</cda_stall>
        <cma_stall>0</cma_stall>
        <cp>-0.30 0.75 -0.005</cp>
        <area>0.10</area>
        <air_density>1.2041</air_density>
        <forward>1 0 0</forward>
        <upward>0 0 1</upward>
        <link_name>skywalker_x8_blue::left_elevon</link_name>
      </plugin>
      <plugin name='x8_elevonright_lift' filename='libLiftDragPlugin.so'>
        <a0>0.15</a0>
        <cla>6.8</cla>
        <cda>0.06417112299</cda>
        <cma>-1.8</cma>
        <alpha_stall>0.6391428111</alpha_stall>
        <cla_stall>-3.85</cla_stall>
        <cda_stall>-0.9233984055</cda_stall>
        <cma_stall>0</cma_stall>
        <cp>-0.30 -0.75 -0.005</cp>
        <area>0.10</area>
        <air_density>1.2041</air_density>
        <forward>1 0 0</forward>
        <upward>0 0 1</upward>
        <link_name>skywalker_x8_blue::right_elevon</link_name>
      </plugin>
      <plugin name='x8_propeller1_lift' filename='libLiftDragPlugin.so'>
        <a0>0.30</a0>
        <alpha_stall>1.4</alpha_stall>
        <cla>4.2500</cla>
        <cda>0.10</cda>
        <cma>0.00</cma>
        <cla_stall>-0.025</cla_stall>
        <cda_stall>0.0</cda_stall>
        <cma_stall>0.0</cma_stall>
        <area>0.02</area>
        <air_density>1.2041</air_density>
        <cp>0.074205 0 0</cp>
        <forward>0 1 0</forward>
        <upward>0 0 1</upward>
        <link_name>skywalker_x8_blue::rotor_pusher</link_name>
      </plugin>
      <plugin name='x8_propeller2_lift' filename='libLiftDragPlugin.so'>
        <a0>0.30</a0>
        <alpha_stall>1.4</alpha_stall>
        <cla>4.2500</cla>
        <cda>0.10</cda>
        <cma>0.00</cma>
        <cla_stall>-0.025</cla_stall>
        <cda_stall>0.0</cda_stall>
        <cma_stall>0.0</cma_stall>
        <area>0.02</area>
        <air_density>1.2041</air_density>
        <cp>-0.074205 0 0</cp>
        <forward>0 -1 0</forward>
        <upward>0 0 1</upward>
        <link_name>skywalker_x8_blue::rotor_pusher</link_name>
      </plugin>
      <plugin name='left_winglet_lift' filename='libLiftDragPlugin.so'>
        <a0>0.0</a0>
        <cla>4.752798721</cla>
        <cda>0.6417112299</cda>
        <cma>-1.8</cma>
        <alpha_stall>0.3391428111</alpha_stall>
        <cla_stall>-3.85</cla_stall>
        <cda_stall>-0.9233984055</cda_stall>
        <cma_stall>0</cma_stall>
        <cp>-0.36 1.04 0.08</cp>
        <area>0.12</area>
        <air_density>1.2041</air_density>
        <forward>1 0 0</forward>
        <upward>0 1 0</upward>
        <link_name>skywalker_x8_blue::base_link</link_name>
      </plugin>
      <plugin name='right_winglet_lift' filename='libLiftDragPlugin.so'>
        <a0>0.0</a0>
        <cla>4.752798721</cla>
        <cda>0.6417112299</cda>
        <cma>-1.8</cma>
        <alpha_stall>0.3391428111</alpha_stall>
        <cla_stall>-3.85</cla_stall>
        <cda_stall>-0.9233984055</cda_stall>
        <cma_stall>0</cma_stall>
        <cp>-0.36 -1.04 0.08</cp>
        <area>0.12</area>
        <air_density>1.2041</air_density>
        <forward>1 0 0</forward>
        <upward>0 -1 0</upward>
        <link_name>skywalker_x8_blue::base_link</link_name>
      </plugin>
      <plugin name='ArduPilotPlugin' filename='libArduPilotPlugin.so'>
        <fdm_addr>127.0.0.1</fdm_addr>
        <fdm_port_in>9022</fdm_port_in>
        <fdm_port_out>9023</fdm_port_out>
        <connectionTimeoutMaxCount>5</connectionTimeoutMaxCount>
        <lock_step>1</lock_step>
        <modelXYZToAirplaneXForwardZDown>0 0 0 3.141593 0 0</modelXYZToAirplaneXForwardZDown>
        <gazeboXYZToNED>0 0 0 3.141593 0 0</gazeboXYZToNED>
        <imuName>imu_sensor</imuName>
        <control channel='0'>
          <jointName>skywalker_x8_blue::left_elevon_joint</jointName>
          <multiplier>1.048</multiplier>
          <offset>-0.5</offset>
          <servo_min>1100</servo_min>
          <servo_max>1900</servo_max>
          <type>POSITION</type>
          <p_gain>10.0</p_gain>
          <i_gain>0</i_gain>
          <d_gain>0</d_gain>
          <i_max>0</i_max>
          <i_min>0</i_min>
          <cmd_max>2.5</cmd_max>
          <cmd_min>-2.5</cmd_min>
        </control>
        <control channel='1'>
          <jointName>skywalker_x8_blue::right_elevon_joint</jointName>
          <multiplier>1.048</multiplier>
          <offset>-0.5</offset>
          <servo_min>1100</servo_min>
          <servo_max>1900</servo_max>
          <type>POSITION</type>
          <p_gain>10.0</p_gain>
          <i_gain>0</i_gain>
          <d_gain>0</d_gain>
          <i_max>0</i_max>
          <i_min>0</i_min>
          <cmd_max>2.5</cmd_max>
          <cmd_min>-2.5</cmd_min>
        </control>
        <control channel='2'>
          <jointName>skywalker_x8_blue::rotor_pusher_joint</jointName>
          <multiplier>838</multiplier>
          <offset>0</offset>
          <servo_min>1200</servo_min>
          <servo_max>2000</servo_max>
          <type>VELOCITY</type>
          <p_gain>0.20</p_gain>
          <i_gain>0</i_gain>
          <d_gain>0</d_gain>
          <i_max>0</i_max>
          <i_min>0</i_min>
          <cmd_max>2.5</cmd_max>
          <cmd_min>-2.5</cmd_min>
        </control>
      </plugin>
      <pose frame=''>-3 1.732 0 0 -0 0</pose>
    </model>
    <gravity>0 0 -9.8</gravity>
    <magnetic_field>6e-06 2.3e-05 -4.2e-05</magnetic_field>
    <atmosphere type='adiabatic'/>
    <wind/>
    <spherical_coordinates>
      <surface_model>EARTH_WGS84</surface_model>
      <latitude_deg>0</latitude_deg>
      <longitude_deg>0</longitude_deg>
      <elevation>0</elevation>
      <heading_deg>0</heading_deg>
    </spherical_coordinates>
   
    <model name='Obstacle'>
      <link name='link_0'>
        <inertial>
          <mass>1</mass>
          <inertia>
            <ixx>0.145833</ixx>
            <ixy>0</ixy>
            <ixz>0</ixz>
            <iyy>0.145833</iyy>
            <iyz>0</iyz>
            <izz>0.125</izz>
          </inertia>
          <pose frame=''>0 0 0 0 -0 0</pose>
        </inertial>
        <pose frame=''>250 -256.667 0.5 0 -0 0</pose>
        <gravity>1</gravity>
        <self_collide>0</self_collide>
        <kinematic>0</kinematic>
        <enable_wind>0</enable_wind>
        <visual name='visual'>
          <pose frame=''>0 0 0 0 -0 0</pose>
          <geometry>
            <cylinder>
              <radius>40</radius>
              <length>75</length>
            </cylinder>
          </geometry>
          <material>
            <lighting>1</lighting>
            <script>
              <uri>file://media/materials/scripts/gazebo.material</uri>
              <name>Gazebo/Grey</name>
            </script>
            <shader type='pixel'>
              <normal_map>__default__</normal_map>
            </shader>
            <ambient>0.3 0.3 0.3 1</ambient>
            <diffuse>0.7 0.7 0.7 1</diffuse>
            <specular>0.01 0.01 0.01 1</specular>
            <emissive>0 0 0 1</emissive>
          </material>
          <transparency>0</transparency>
          <cast_shadows>1</cast_shadows>
        </visual>
        <collision name='collision'>
          <laser_retro>0</laser_retro>
          <max_contacts>10</max_contacts>
          <pose frame=''>0 0 0 0 -0 0</pose>
          <geometry>
            <cylinder>
              <radius>40</radius>
              <length>75</length>
            </cylinder>
          </geometry>
          <surface>
            <friction>
              <ode>
                <mu>1</mu>
                <mu2>1</mu2>
                <fdir1>0 0 0</fdir1>
                <slip1>0</slip1>
                <slip2>0</slip2>
              </ode>
              <torsional>
                <coefficient>1</coefficient>
                <patch_radius>0</patch_radius>
                <surface_radius>0</surface_radius>
                <use_patch_radius>1</use_patch_radius>
                <ode>
                  <slip>0</slip>
                </ode>
              </torsional>
            </friction>
            <bounce>
              <restitution_coefficient>0</restitution_coefficient>
              <threshold>1e+06</threshold>
            </bounce>
            <contact>
              <collide_without_contact>0</collide_without_contact>
              <collide_without_contact_bitmask>1</collide_without_contact_bitmask>
              <collide_bitmask>1</collide_bitmask>
              <ode>
                <soft_cfm>0</soft_cfm>
                <soft_erp>0.2</soft_erp>
                <kp>1e+13</kp>
                <kd>1</kd>
                <max_vel>0.01</max_vel>
                <min_depth>0</min_depth>
              </ode>
              <bullet>
                <split_impulse>1</split_impulse>
                <split_impulse_penetration_threshold>-0.01</split_impulse_penetration_threshold>
                <soft_cfm>0</soft_cfm>
                <soft_erp>0.2</soft_erp>
                <kp>1e+13</kp>
                <kd>1</kd>
              </bullet>
            </contact>
          </surface>
        </collision>
      </link>
      <link name='link_4'>
        <inertial>
          <mass>1</mass>
          <inertia>
            <ixx>0.145833</ixx>
            <ixy>0</ixy>
            <ixz>0</ixz>
            <iyy>0.145833</iyy>
            <iyz>0</iyz>
            <izz>0.125</izz>
          </inertia>
          <pose frame=''>0 0 0 0 -0 0</pose>
        </inertial>
        <pose frame=''>0 -156.667 0.5 0 -0 0</pose>
        <gravity>1</gravity>
        <self_collide>0</self_collide>
        <kinematic>0</kinematic>
        <enable_wind>0</enable_wind>
        <visual name='visual'>
          <pose frame=''>0 0 0 0 -0 0</pose>
          <geometry>
            <cylinder>
              <radius>60</radius>
              <length>55</length>
            </cylinder>
          </geometry>
          <material>
            <lighting>1</lighting>
            <script>
              <uri>file://media/materials/scripts/gazebo.material</uri>
              <name>Gazebo/Grey</name>
            </script>
            <shader type='pixel'>
              <normal_map>__default__</normal_map>
            </shader>
            <ambient>0.3 0.3 0.3 1</ambient>
            <diffuse>0.7 0.7 0.7 1</diffuse>
            <specular>0.01 0.01 0.01 1</specular>
            <emissive>0 0 0 1</emissive>
          </material>
          <transparency>0</transparency>
          <cast_shadows>1</cast_shadows>
        </visual>
        <collision name='collision'>
          <laser_retro>0</laser_retro>
          <max_contacts>10</max_contacts>
          <pose frame=''>0 0 0 0 -0 0</pose>
          <geometry>
            <cylinder>
              <radius>60</radius>
              <length>55</length>
            </cylinder>
          </geometry>
          <surface>
            <friction>
              <ode>
                <mu>1</mu>
                <mu2>1</mu2>
                <fdir1>0 0 0</fdir1>
                <slip1>0</slip1>
                <slip2>0</slip2>
              </ode>
              <torsional>
                <coefficient>1</coefficient>
                <patch_radius>0</patch_radius>
                <surface_radius>0</surface_radius>
                <use_patch_radius>1</use_patch_radius>
                <ode>
                  <slip>0</slip>
                </ode>
              </torsional>
            </friction>
            <bounce>
              <restitution_coefficient>0</restitution_coefficient>
              <threshold>1e+06</threshold>
            </bounce>
            <contact>
              <collide_without_contact>0</collide_without_contact>
              <collide_without_contact_bitmask>1</collide_without_contact_bitmask>
              <collide_bitmask>1</collide_bitmask>
              <ode>
                <soft_cfm>0</soft_cfm>
                <soft_erp>0.2</soft_erp>
                <kp>1e+13</kp>
                <kd>1</kd>
                <max_vel>0.01</max_vel>
                <min_depth>0</min_depth>
              </ode>
              <bullet>
                <split_impulse>1</split_impulse>
                <split_impulse_penetration_threshold>-0.01</split_impulse_penetration_threshold>
                <soft_cfm>0</soft_cfm>
                <soft_erp>0.2</soft_erp>
                <kp>1e+13</kp>
                <kd>1</kd>
              </bullet>
            </contact>
          </surface>
        </collision>
      </link>
      <link name='link_5'>
        <inertial>
          <mass>1</mass>
          <inertia>
            <ixx>0.145833</ixx>
            <ixy>0</ixy>
            <ixz>0</ixz>
            <iyy>0.145833</iyy>
            <iyz>0</iyz>
            <izz>0.125</izz>
          </inertia>
          <pose frame=''>0 0 0 0 -0 0</pose>
        </inertial>
        <pose frame=''>425 -336.667 0.5 0 -0 0</pose>
        <gravity>1</gravity>
        <self_collide>0</self_collide>
        <kinematic>0</kinematic>
        <enable_wind>0</enable_wind>
        <visual name='visual'>
          <pose frame=''>0 0 0 0 -0 0</pose>
          <geometry>
            <cylinder>
              <radius>30</radius>
              <length>70</length>
            </cylinder>
          </geometry>
          <material>
            <lighting>1</lighting>
            <script>
              <uri>file://media/materials/scripts/gazebo.material</uri>
              <name>Gazebo/Grey</name>
            </script>
            <shader type='pixel'>
              <normal_map>__default__</normal_map>
            </shader>
            <ambient>0.3 0.3 0.3 1</ambient>
            <diffuse>0.7 0.7 0.7 1</diffuse>
            <specular>0.01 0.01 0.01 1</specular>
            <emissive>0 0 0 1</emissive>
          </material>
          <transparency>0</transparency>
          <cast_shadows>1</cast_shadows>
        </visual>
        <collision name='collision'>
          <laser_retro>0</laser_retro>
          <max_contacts>10</max_contacts>
          <pose frame=''>0 0 0 0 -0 0</pose>
          <geometry>
            <cylinder>
              <radius>30</radius>
              <length>70</length>
            </cylinder>
          </geometry>
          <surface>
            <friction>
              <ode>
                <mu>1</mu>
                <mu2>1</mu2>
                <fdir1>0 0 0</fdir1>
                <slip1>0</slip1>
                <slip2>0</slip2>
              </ode>
              <torsional>
                <coefficient>1</coefficient>
                <patch_radius>0</patch_radius>
                <surface_radius>0</surface_radius>
                <use_patch_radius>1</use_patch_radius>
                <ode>
                  <slip>0</slip>
                </ode>
              </torsional>
            </friction>
            <bounce>
              <restitution_coefficient>0</restitution_coefficient>
              <threshold>1e+06</threshold>
            </bounce>
            <contact>
              <collide_without_contact>0</collide_without_contact>
              <collide_without_contact_bitmask>1</collide_without_contact_bitmask>
              <collide_bitmask>1</collide_bitmask>
              <ode>
                <soft_cfm>0</soft_cfm>
                <soft_erp>0.2</soft_erp>
                <kp>1e+13</kp>
                <kd>1</kd>
                <max_vel>0.01</max_vel>
                <min_depth>0</min_depth>
              </ode>
              <bullet>
                <split_impulse>1</split_impulse>
                <split_impulse_penetration_threshold>-0.01</split_impulse_penetration_threshold>
                <soft_cfm>0</soft_cfm>
                <soft_erp>0.2</soft_erp>
                <kp>1e+13</kp>
                <kd>1</kd>
              </bullet>
            </contact>
          </surface>
        </collision>
      </link>
      <static>0</static>
      <allow_auto_disable>1</allow_auto_disable>
      <pose frame=''>100 -43.3333 0 0 -0 0</pose>
    </model>
    <state world_name='default'>
      <sim_time>12 510000000</sim_time>
      <real_time>53 916523727</real_time>
      <wall_time>1694539269 698375110</wall_time>
      <iterations>12510</iterations>
      <model name='Obstacle'>
        <pose frame=''>100 -43.3333 0 0 -0 0</pose>
        <scale>1 1 1</scale>
        <link name='link_0'>
          <pose frame=''>350 -300 0.5 0 -0 0</pose>
          <velocity>0 0 0 0 -0 0</velocity>
          <acceleration>0 0 0 0 -0 0</acceleration>
          <wrench>0 0 0 0 -0 0</wrench>
        </link>
        <link name='link_4'>
          <pose frame=''>100 -200 0.5 0 -0 0</pose>
          <velocity>0 0 0 0 -0 0</velocity>
          <acceleration>0 0 0 0 -0 0</acceleration>
          <wrench>0 0 0 0 -0 0</wrench>
        </link>
        <link name='link_5'>
          <pose frame=''>525 -380 0.5 0 -0 0</pose>
          <velocity>0 0 0 0 -0 0</velocity>
          <acceleration>0 0 0 0 -0 0</acceleration>
          <wrench>0 0 0 0 -0 0</wrench>
        </link>
      </model>
      <model name='SkywalkerX8_Blue'>
        <pose frame=''>-3.00012 1.732 -0.076 0 -0 2e-06</pose>
        <scale>1 1 1</scale>
        <link name='skywalker_x8_blue::base_link'>
          <pose frame=''>-3.00012 1.732 0.17 0 -0 2e-06</pose>
          <velocity>0.002118 0 0.005003 -2e-06 0.012476 1e-06</velocity>
          <acceleration>7.60424 0.000497 8.15503 -0.002171 0.79064 0.001294</acceleration>
          <wrench>34.2191 0.002237 36.6977 0 -0 0</wrench>
        </link>
        <link name='skywalker_x8_blue::cam_link'>
          <pose frame=''>-3.00012 1.732 0.17 0 -0 2e-06</pose>
          <velocity>0.002107 1e-06 0.005003 -1e-06 0.012498 5e-06</velocity>
          <acceleration>7.58639 0.001449 8.15522 -0.001473 0.826933 0.006579</acceleration>
          <wrench>0.075864 1.4e-05 0.081552 0 -0 0</wrench>
        </link>
        <link name='skywalker_x8_blue::imu_link'>
          <pose frame=''>-3.00012 1.732 0.17 0 -0 2e-06</pose>
          <velocity>0.002107 1e-06 0.005003 -1e-06 0.012499 6e-06</velocity>
          <acceleration>7.58657 0.001452 8.15514 -0.001328 0.82646 0.008004</acceleration>
          <wrench>1.13799 0.000218 1.22327 0 -0 0</wrench>
        </link>
        <link name='skywalker_x8_blue::left_elevon'>
          <pose frame=''>-3.01137 1.72895 0.117027 -0.15227 0.509669 -0.039736</pose>
          <velocity>0.00227 0.000236 0.006606 0.005048 -0.005151 -8e-06</velocity>
          <acceleration>7.36971 0.06846 22.1883 -0.422954 1.27536 -0.668051</acceleration>
          <wrench>0.736971 0.006846 2.21883 0 -0 0</wrench>
        </link>
        <link name='skywalker_x8_blue::right_elevon'>
          <pose frame=''>-3.01137 1.73506 0.117027 0.15227 0.509669 0.039739</pose>
          <velocity>0.002287 -0.000235 0.006684 -0.005033 -0.005394 1.4e-05</velocity>
          <acceleration>7.38611 -0.070659 22.1899 -0.103285 1.56675 0.984486</acceleration>
          <wrench>0.738611 -0.007066 2.21899 0 -0 0</wrench>
        </link>
        <link name='skywalker_x8_blue::rotor_pusher'>
          <pose frame=''>-3.38512 1.732 0.17 -1.04513 1.56921 -1.04513</pose>
          <velocity>0.002107 -1e-06 0.009815 -0.000181 0.012498 5e-06</velocity>
          <acceleration>7.58661 -0.001084 25.4068 -0.005171 0.828438 1.10363</acceleration>
          <wrench>0.189665 -2.7e-05 0.635169 0 -0 0</wrench>
        </link>
      </model>
      <model name='SkywalkerX8_Green'>
        <pose frame=''>-3.00012 -1.732 -0.076 -0 -0 -0</pose>
        <scale>1 1 1</scale>
        <link name='skywalker_x8_green::base_link'>
          <pose frame=''>-3.00012 -1.732 0.17 -0 -0 -0</pose>
          <velocity>0.002118 0 0.005003 -2e-06 0.012476 1e-06</velocity>
          <acceleration>7.60416 -0.000177 8.15518 0.001842 0.790619 0.001322</acceleration>
          <wrench>34.2187 -0.000797 36.6983 0 -0 0</wrench>
        </link>
        <link name='skywalker_x8_green::cam_link'>
          <pose frame=''>-3.00012 -1.732 0.17 -0 -0 -0</pose>
          <velocity>0.002107 1e-06 0.005003 -1e-06 0.012498 5e-06</velocity>
          <acceleration>7.58616 0.000659 8.15536 0.002364 0.827208 0.006092</acceleration>
          <wrench>0.075862 7e-06 0.081554 0 -0 0</wrench>
        </link>
        <link name='skywalker_x8_green::imu_link'>
          <pose frame=''>-3.00012 -1.732 0.17 -0 -0 -0</pose>
          <velocity>0.002107 1e-06 0.005003 -1e-06 0.012499 7e-06</velocity>
          <acceleration>7.58633 0.000662 8.15528 0.002459 0.826747 0.007592</acceleration>
          <wrench>1.13795 9.9e-05 1.22329 0 -0 0</wrench>
        </link>
        <link name='skywalker_x8_green::left_elevon'>
          <pose frame=''>-3.01137 -1.73505 0.117027 -0.152268 0.509663 -0.039737</pose>
          <velocity>0.001896 0.000135 0.005859 0.002944 0.002628 -9e-06</velocity>
          <acceleration>7.29044 0.046294 22.0463 -2.09949 -1.53078 -2.20811</acceleration>
          <wrench>0.729044 0.004629 2.20463 0 -0 0</wrench>
        </link>
        <link name='skywalker_x8_green::right_elevon'>
          <pose frame=''>-3.01138 -1.72894 0.117027 0.15227 0.509669 0.039737</pose>
          <velocity>0.002289 -0.000236 0.006686 -0.005042 -0.005425 1.4e-05</velocity>
          <acceleration>7.38526 -0.07124 22.1891 3.01596 1.53257 -2.14715</acceleration>
          <wrench>0.738526 -0.007124 2.21891 0 -0 0</wrench>
        </link>
        <link name='skywalker_x8_green::rotor_pusher'>
          <pose frame=''>-3.38512 -1.732 0.17 -1.04532 1.56921 -1.04532</pose>
          <velocity>0.002107 -1e-06 0.009815 -0.000181 0.012498 5e-06</velocity>
          <acceleration>7.58637 -0.001686 25.407 -0.005205 0.828704 1.09568</acceleration>
          <wrench>0.189659 -4.2e-05 0.635176 0 -0 0</wrench>
        </link>
      </model>
      <model name='SkywalkerX8_Red'>
        <pose frame=''>-0.000119 1e-06 -0.076 0 -0 2e-06</pose>
        <scale>1 1 1</scale>
        <link name='skywalker_x8_red::base_link'>
          <pose frame=''>-0.000119 1e-06 0.17 0 -0 2e-06</pose>
          <velocity>0.002118 -0 0.005003 2e-06 0.012476 -1e-06</velocity>
          <acceleration>7.60433 -0.000372 8.15462 0.00139 0.791161 -0.001306</acceleration>
          <wrench>34.2195 -0.001672 36.6958 0 -0 0</wrench>
        </link>
        <link name='skywalker_x8_red::cam_link'>
          <pose frame=''>-0.000119 1e-06 0.17 0 -0 2e-06</pose>
          <velocity>0.002107 -1e-06 0.005003 1e-06 0.012498 -5e-06</velocity>
          <acceleration>7.58647 -0.001178 8.15481 0.000939 0.827467 -0.006008</acceleration>
          <wrench>0.075865 -1.2e-05 0.081548 0 -0 0</wrench>
        </link>
        <link name='skywalker_x8_red::imu_link'>
          <pose frame=''>-0.000119 1e-06 0.17 0 -0 2e-06</pose>
          <velocity>0.002107 -1e-06 0.005003 1e-06 0.012499 -6e-06</velocity>
          <acceleration>7.58665 -0.001181 8.15472 0.000914 0.826993 -0.008028</acceleration>
          <wrench>1.138 -0.000177 1.22321 0 -0 0</wrench>
        </link>
        <link name='skywalker_x8_red::left_elevon'>
          <pose frame=''>-0.011374 -0.003054 0.117027 -0.15227 0.509669 -0.039736</pose>
          <velocity>0.002288 0.000235 0.006689 0.005034 -0.005406 -1.4e-05</velocity>
          <acceleration>7.38563 0.070811 22.1919 -0.066558 1.53561 -0.877966</acceleration>
          <wrench>0.738563 0.007081 2.21919 0 -0 0</wrench>
        </link>
        <link name='skywalker_x8_red::right_elevon'>
          <pose frame=''>-0.011374 0.003055 0.117027 0.15227 0.509669 0.039739</pose>
          <velocity>0.002278 -0.000239 0.00662 -0.005101 -0.005335 8e-06</velocity>
          <acceleration>7.37049 -0.068368 22.1861 -0.080512 1.33023 0.98471</acceleration>
          <wrench>0.737049 -0.006837 2.21861 0 -0 0</wrench>
        </link>
        <link name='skywalker_x8_red::rotor_pusher'>
          <pose frame=''>-0.385119 0 0.17 -1.04513 1.56921 -1.04513</pose>
          <velocity>0.002107 1e-06 0.009815 -0.000181 0.012498 -5e-06</velocity>
          <acceleration>7.58668 0.001135 25.4066 -0.005004 0.828694 0.887279</acceleration>
          <wrench>0.189667 2.8e-05 0.635164 0 -0 0</wrench>
        </link>
      </model>
      <model name='ground_plane'>
        <pose frame=''>0 0 0 0 -0 0</pose>
        <scale>1 1 1</scale>
        <link name='link'>
          <pose frame=''>0 0 0 0 -0 0</pose>
          <velocity>0 0 0 0 -0 0</velocity>
          <acceleration>0 0 0 0 -0 0</acceleration>
          <wrench>0 0 0 0 -0 0</wrench>
        </link>
      </model>
      <light name='sun'>
        <pose frame=''>0 0 10 0 -0 0</pose>
      </light>
    </state>
    <gui fullscreen='0'>
      <camera name='user_camera'>
        <pose frame=''>-118.492 -9.09112 43.7182 0 0.211643 -0.279803</pose>
        <view_controller>orbit</view_controller>
        <projection_type>perspective</projection_type>
      </camera>
    </gui>
  </world>
</sdf>
